[2024-01-20T19:14:16.653+0000] {taskinstance.py:1159} INFO - Dependencies all met for dep_context=non-requeueable deps ti=<TaskInstance: Kafka_Producer_4.coinMarket scheduled__2024-01-20T19:12:13.366116+00:00 [queued]>
[2024-01-20T19:14:16.662+0000] {taskinstance.py:1159} INFO - Dependencies all met for dep_context=requeueable deps ti=<TaskInstance: Kafka_Producer_4.coinMarket scheduled__2024-01-20T19:12:13.366116+00:00 [queued]>
[2024-01-20T19:14:16.663+0000] {taskinstance.py:1361} INFO - Starting attempt 1 of 1
[2024-01-20T19:14:16.682+0000] {taskinstance.py:1382} INFO - Executing <Task(PythonOperator): coinMarket> on 2024-01-20 19:12:13.366116+00:00
[2024-01-20T19:14:16.691+0000] {standard_task_runner.py:57} INFO - Started process 320 to run task
[2024-01-20T19:14:16.695+0000] {standard_task_runner.py:84} INFO - Running: ['***', 'tasks', 'run', 'Kafka_Producer_4', 'coinMarket', 'scheduled__2024-01-20T19:12:13.366116+00:00', '--job-id', '1118', '--raw', '--subdir', 'DAGS_FOLDER/kafka_stream_4.py', '--cfg-path', '/tmp/tmpjv4jidyp']
[2024-01-20T19:14:16.698+0000] {standard_task_runner.py:85} INFO - Job 1118: Subtask coinMarket
[2024-01-20T19:14:16.793+0000] {task_command.py:415} INFO - Running <TaskInstance: Kafka_Producer_4.coinMarket scheduled__2024-01-20T19:12:13.366116+00:00 [running]> on host 45c5bfab8aa1
[2024-01-20T19:14:16.910+0000] {taskinstance.py:1660} INFO - Exporting env vars: AIRFLOW_CTX_DAG_OWNER='me' AIRFLOW_CTX_DAG_ID='Kafka_Producer_4' AIRFLOW_CTX_TASK_ID='coinMarket' AIRFLOW_CTX_EXECUTION_DATE='2024-01-20T19:12:13.366116+00:00' AIRFLOW_CTX_TRY_NUMBER='1' AIRFLOW_CTX_DAG_RUN_ID='scheduled__2024-01-20T19:12:13.366116+00:00'
[2024-01-20T19:14:17.843+0000] {taskinstance.py:1943} ERROR - Task failed with exception
Traceback (most recent call last):
  File "/home/airflow/.local/lib/python3.9/site-packages/airflow/operators/python.py", line 192, in execute
    return_value = self.execute_callable()
  File "/home/airflow/.local/lib/python3.9/site-packages/airflow/operators/python.py", line 209, in execute_callable
    return self.python_callable(*self.op_args, **self.op_kwargs)
  File "/opt/airflow/dags/kafka_stream_4.py", line 43, in coinMarket_function
    bitcoin_data = next((crypto for crypto in data['data'] if crypto['symbol'] == 'BTC'), None)
KeyError: 'data'
[2024-01-20T19:14:17.860+0000] {taskinstance.py:1400} INFO - Marking task as FAILED. dag_id=Kafka_Producer_4, task_id=coinMarket, execution_date=20240120T191213, start_date=20240120T191416, end_date=20240120T191417
[2024-01-20T19:14:17.877+0000] {standard_task_runner.py:104} ERROR - Failed to execute job 1118 for task coinMarket ('data'; 320)
[2024-01-20T19:14:17.915+0000] {local_task_job_runner.py:228} INFO - Task exited with return code 1
[2024-01-20T19:14:17.940+0000] {taskinstance.py:2784} INFO - 0 downstream tasks scheduled from follow-on schedule check
