[2024-01-20T19:12:54.250+0000] {taskinstance.py:1159} INFO - Dependencies all met for dep_context=non-requeueable deps ti=<TaskInstance: Kafka_Producer_4.coinMarket scheduled__2024-01-20T19:10:13.366116+00:00 [queued]>
[2024-01-20T19:12:54.264+0000] {taskinstance.py:1159} INFO - Dependencies all met for dep_context=requeueable deps ti=<TaskInstance: Kafka_Producer_4.coinMarket scheduled__2024-01-20T19:10:13.366116+00:00 [queued]>
[2024-01-20T19:12:54.265+0000] {taskinstance.py:1361} INFO - Starting attempt 1 of 1
[2024-01-20T19:12:54.283+0000] {taskinstance.py:1382} INFO - Executing <Task(PythonOperator): coinMarket> on 2024-01-20 19:10:13.366116+00:00
[2024-01-20T19:12:54.345+0000] {standard_task_runner.py:57} INFO - Started process 259 to run task
[2024-01-20T19:12:54.349+0000] {standard_task_runner.py:84} INFO - Running: ['***', 'tasks', 'run', 'Kafka_Producer_4', 'coinMarket', 'scheduled__2024-01-20T19:10:13.366116+00:00', '--job-id', '1107', '--raw', '--subdir', 'DAGS_FOLDER/kafka_stream_4.py', '--cfg-path', '/tmp/tmp8i_bynsr']
[2024-01-20T19:12:54.351+0000] {standard_task_runner.py:85} INFO - Job 1107: Subtask coinMarket
[2024-01-20T19:12:54.424+0000] {task_command.py:415} INFO - Running <TaskInstance: Kafka_Producer_4.coinMarket scheduled__2024-01-20T19:10:13.366116+00:00 [running]> on host 45c5bfab8aa1
[2024-01-20T19:12:54.534+0000] {taskinstance.py:1660} INFO - Exporting env vars: AIRFLOW_CTX_DAG_OWNER='me' AIRFLOW_CTX_DAG_ID='Kafka_Producer_4' AIRFLOW_CTX_TASK_ID='coinMarket' AIRFLOW_CTX_EXECUTION_DATE='2024-01-20T19:10:13.366116+00:00' AIRFLOW_CTX_TRY_NUMBER='1' AIRFLOW_CTX_DAG_RUN_ID='scheduled__2024-01-20T19:10:13.366116+00:00'
[2024-01-20T19:12:55.043+0000] {taskinstance.py:1943} ERROR - Task failed with exception
Traceback (most recent call last):
  File "/home/airflow/.local/lib/python3.9/site-packages/airflow/operators/python.py", line 192, in execute
    return_value = self.execute_callable()
  File "/home/airflow/.local/lib/python3.9/site-packages/airflow/operators/python.py", line 209, in execute_callable
    return self.python_callable(*self.op_args, **self.op_kwargs)
  File "/opt/airflow/dags/kafka_stream_4.py", line 43, in coinMarket_function
    bitcoin_data = next((crypto for crypto in data['data'] if crypto['symbol'] == 'BTC'), None)
KeyError: 'data'
[2024-01-20T19:12:55.059+0000] {taskinstance.py:1400} INFO - Marking task as FAILED. dag_id=Kafka_Producer_4, task_id=coinMarket, execution_date=20240120T191013, start_date=20240120T191254, end_date=20240120T191255
[2024-01-20T19:12:55.074+0000] {standard_task_runner.py:104} ERROR - Failed to execute job 1107 for task coinMarket ('data'; 259)
[2024-01-20T19:12:55.084+0000] {local_task_job_runner.py:228} INFO - Task exited with return code 1
[2024-01-20T19:12:55.110+0000] {taskinstance.py:2784} INFO - 0 downstream tasks scheduled from follow-on schedule check
